source/output/09.csv
time,stock,vwap
9:00:00,A,73.92
9:00:00,AA,28.84
9:00:00,AABA,66.6
9:00:00,AAC,2.22
9:00:00,AAL,36.47
9:00:00,AAME,2.75
9:00:00,AAN,49.1
9:00:00,AAOI,16.59
9:00:00,AAON,35.62
9:00:00,AAP,158.02
9:00:00,AAPL,162.03
9:00:00,AAT,42.04
9:00:00,AAWW,50.83
9:00:00,AAXJ,67.43
9:00:00,AAXN,48.71
9:00:00,AB,30.03
9:00:00,ABB,19.08
9:00:00,ABBV,77.71
9:00:00,ABC,79.67
9:00:00,ABCB,37.85
9:00:00,ABEO,6.52
9:00:00,ABEV,4.76
9:00:00,ABG,69.18
9:00:00,ABIL,2.01
9:00:00,ABIO,0.4
9:00:00,ABM,33.15
9:00:00,ABMD,332.43
9:00:00,ABR,11.67
9:00:00,ABT,69.98
9:00:00,ABTX,36.18
9:00:00,ACA,29.46
9:00:00,ACAD,22.6
9:00:00,ACB,6.91
9:00:00,ACBI,18.41
9:00:00,ACC,45.8
9:00:00,ACCO,8.86
9:00:00,ACER,22.91
9:00:00,ACGL,28.8
9:00:00,ACGLO,22.72
9:00:00,ACGLP,22.14
9:00:00,ACH,9.01
9:00:00,ACHC,27.63
9:00:00,ACHN,2.14
9:00:00,ACHV,1.42
9:00:00,ACIA,42.8
9:00:00,ACIU,3.46
9:00:00,ACIW,28.6
9:00:00,ACLS,20.55
9:00:00,ACM,30.15
9:00:00,ACMR,9.46
9:00:00,ACN,152.13
9:00:00,ACOR,15.88
9:00:00,ACP,11.54
9:00:00,ACRS,6.86
9:00:00,ACRX,2.41
9:00:00,ACT,22.88
9:00:00,ACWI,68.25
9:00:00,ADAP,4.68
9:00:00,ADBE,241.19
9:00:00,ADC,64.42
9:00:00,ADES,11.47
9:00:00,ADI,97.62
9:00:00,ADIL,4.99
9:00:00,ADM,44.29
9:00:00,ADMP,3.12
9:00:00,ADMS,8.51
9:00:00,ADNT,18.85
9:00:00,ADOM,0.26
9:00:00,ADP,136.66
9:00:00,ADRO,2.45
9:00:00,ADS,177.31
9:00:00,ADSK,141.64
9:00:00,ADSW,24.7
9:00:00,ADT,7.18
9:00:00,ADTN,14.34
9:00:00,ADUS,59.6
9:00:00,ADVM,2.97
9:00:00,ADXS,0.35
9:00:00,AE,39.82
9:00:00,AEE,67.46
9:00:00,AEG,5.2
9:00:00,AEGN,17.75
9:00:00,AEHR,1.2
9:00:00,AEIS,50.34
9:00:00,AEL,30.28
9:00:00,AEM,42.44
9:00:00,AEMD,1.33
9:00:00,AEO,20.98
9:00:00,AEP,76.99
9:00:00,AER,47.47
9:00:00,AERI,46.42
9:00:00,AES,16.09
9:00:00,AFG,94.08
9:00:00,AFI,13.02
9:00:00,AFIN,12.88
9:00:00,AFL,47.14
9:00:00,AFSI-B,7.79
9:00:00,AFSI-F,7.53
9:00:00,AFSS,14.0
9:00:00,AG,5.72
9:00:00,AGCO,63.33
9:00:00,AGE,4.05
9:00:00,AGEN,3.34
9:00:00,AGFS,3.96
9:00:00,AGG,106.86
9:00:00,AGI,4.35
9:00:00,AGIO,50.59
9:00:00,AGLE,8.65
9:00:00,AGM,71.58
9:00:00,AGN,142.61
9:00:00,AGNC,17.97
9:00:00,AGR,48.73
9:00:00,AGS,24.58
9:00:00,AGX,42.38
9:00:00,AGYS,17.77
9:00:00,AHC,3.92
9:00:00,AHPI,1.98
9:00:00,AHT,4.8
9:00:00,AHT-I,21.16
9:00:00,AI,8.57
9:00:00,AIG,42.31
9:00:00,AIG+,6.9
9:00:00,AIMC,29.32
9:00:00,AIMT,21.93
9:00:00,AIN,68.01
9:00:00,AINC,65.35
9:00:00,AINV,14.74
9:00:00,AIPT,1.01
9:00:00,AIR,36.49
9:00:00,AIT,58.32
9:00:00,AIV,49.23
9:00:00,AIZ,95.07
9:00:00,AJG,72.04
9:00:00,AJRD,38.67
9:00:00,AKAM,64.25
9:00:00,AKAO,1.68
9:00:00,AKBA,5.44
9:00:00,AKG,0.75
9:00:00,AKR,27.95
9:00:00,AKRX,4.15
9:00:00,AKS,2.71
9:00:00,AKTS,7.29
9:00:00,AL,37.35
9:00:00,ALB,79.01
9:00:00,ALDR,12.22
9:00:00,ALDX,8.53
9:00:00,ALE,74.82
9:00:00,ALG,87.24
9:00:00,ALGN,216.37
9:00:00,ALGT,125.21
9:00:00,ALK,64.26
9:00:00,ALKS,32.54
9:00:00,ALL,86.67
9:00:00,ALLE,84.89
9:00:00,ALLK,39.7
9:00:00,ALLO,30.43
9:00:00,ALLT,6.77
9:00:00,ALLY,26.48
9:00:00,ALNA,7.52
9:00:00,ALNY,78.37
9:00:00,ALOT,19.98
9:00:00,ALQA,2.49
9:00:00,ALRM,62.54
9:00:00,ALSN,48.71
9:00:00,ALT,2.97
9:00:00,ALTM,8.4
9:00:00,ALTR,30.81
9:00:00,ALV,76.56
9:00:00,ALX,329.88
9:00:00,ALXN,119.2
9:00:00,AM,25.91
9:00:00,AMAG,15.4
9:00:00,AMAL,18.8
9:00:00,AMAT,38.84
9:00:00,AMBA,37.63
9:00:00,AMBC,18.54
9:00:00,AMC,14.04
9:00:00,AMCN,0.55
9:00:00,AMCX,61.58
9:00:00,AMD,21.98
9:00:00,AME,71.72
9:00:00,AMED,128.26
9:00:00,AMG,105.23
9:00:00,AMGN,186.61
9:00:00,AMGP,13.68
9:00:00,AMH,22.06
9:00:00,AMJ,25.05
9:00:00,AMKR,7.89
9:00:00,AMLP,9.86
9:00:00,AMN,64.32
9:00:00,AMNB,32.84
9:00:00,AMOT,41.47
9:00:00,AMP,118.82
9:00:00,AMPH,21.97
9:00:00,AMR,1.01
9:00:00,AMRC,14.89
9:00:00,AMRN,16.75
9:00:00,AMRS,2.76
9:00:00,AMRX,12.13
9:00:00,AMSC,12.74
9:00:00,AMSF,59.06
9:00:00,AMSWA,11.1
9:00:00,AMT,170.09
9:00:00,AMTB,13.69
9:00:00,AMTD,55.19
9:00:00,AMWD,66.69
9:00:00,AMX,15.78
9:00:00,AMZA,5.84
9:00:00,AMZN,1634.79
9:00:00,AN,36.94
9:00:00,ANAB,61.97
9:00:00,ANAT,137.45
9:00:00,ANCX,24.15
9:00:00,ANDE,34.22
9:00:00,ANDX,35.77
9:00:00,ANET,207.99
9:00:00,ANF,21.41
9:00:00,ANFI,0.88
9:00:00,ANGI,16.05
9:00:00,ANGL,27.9
9:00:00,ANGO,20.76
9:00:00,ANH,4.46
9:00:00,ANIK,37.34
9:00:00,ANIX,5.28
9:00:00,ANSS,160.41
9:00:00,ANTM,298.87
9:00:00,ANY,2.7
9:00:00,AOBC,11.84
9:00:00,AON,152.76
9:00:00,AOR,42.85
9:00:00,AOS,46.98
9:00:00,AOSL,11.75
9:00:00,AP,3.7
9:00:00,APA,33.13
9:00:00,APAM,22.4
9:00:00,APC,46.97
9:00:00,APD,164.04
9:00:00,APDN,0.46
9:00:00,APEI,29.65
9:00:00,APEN,3.54
9:00:00,APH,86.42
9:00:00,APHA,7.35
9:00:00,APLE,16.0
9:00:00,APLS,13.12
9:00:00,APM,13.86
9:00:00,APO,27.67
9:00:00,APOG,33.56
9:00:00,APOP,2.33
9:00:00,APPF,60.01
9:00:00,APPN,31.58
9:00:00,APRN,1.48
9:00:00,APTV,72.25
9:00:00,APTX,5.35
9:00:00,APU,30.02
9:00:00,APY,33.7
9:00:00,APYX,8.81
9:00:00,AQ,8.7
9:00:00,AQB,2.2
9:00:00,AQMS,2.2
9:00:00,AQST,7.36
9:00:00,AQUA,10.24
9:00:00,AR,10.32
9:00:00,ARAV,3.66
9:00:00,ARAY,4.43
9:00:00,ARC,2.22
9:00:00,ARCB,39.97
9:00:00,ARCC,16.09
9:00:00,ARCH,85.55
9:00:00,ARCI,0.46
9:00:00,ARCO,8.77
9:00:00,ARCT,5.16
9:00:00,ARD,11.82
9:00:00,ARDX,2.1
9:00:00,ARE,128.29
9:00:00,ARES,20.72
9:00:00,AREX,0.99
9:00:00,ARGO,64.06
9:00:00,ARGX,103.32
9:00:00,ARI,17.9
9:00:00,ARKK,41.54
9:00:00,ARKW,48.06
9:00:00,ARLO,6.98
9:00:00,ARMK,32.29
9:00:00,ARNA,44.33
9:00:00,ARNC,18.43
9:00:00,AROC,9.53
9:00:00,AROW,31.32
9:00:00,ARQL,3.38
9:00:00,ARR,21.03
9:00:00,ARRS,31.29
9:00:00,ARRY,18.02
9:00:00,ARTNA,34.7
9:00:00,ARTX,3.49
9:00:00,ARVN,17.08
9:00:00,ARW,74.71
9:00:00,ARWR,13.39
9:00:00,ASA,9.93
9:00:00,ASB,22.09
9:00:00,ASGN,60.96
9:00:00,ASH,76.37
9:00:00,ASHR,23.74
9:00:00,ASIX,30.36
9:00:00,ASLN,3.7
9:00:00,ASMB,21.3
9:00:00,ASML,175.47
9:00:00,ASNA,2.39
9:00:00,ASND,71.58
9:00:00,ASPS,22.76
9:00:00,ASR,180.33
9:00:00,ASRT,4.21
9:00:00,ASRV,4.15
9:00:00,AST,1.04
9:00:00,ASTC,5.03
9:00:00,ASTE,36.4
9:00:00,ASUR,5.54
9:00:00,ASV,3.13
9:00:00,ASX,3.9
9:00:00,ATEC,1.57
9:00:00,ATEN,6.54
9:00:00,ATGE,48.65
9:00:00,ATH,42.18
9:00:00,ATHM,72.36
9:00:00,ATHN,134.37
9:00:00,ATHX,1.58
9:00:00,ATI,26.49
9:00:00,ATISW,0.08
9:00:00,ATKR,22.13
9:00:00,ATLO,25.34
9:00:00,ATNI,73.22
9:00:00,ATNX,11.34
9:00:00,ATO,94.76
9:00:00,ATR,98.03
9:00:00,ATRA,34.56
9:00:00,ATRC,29.53
9:00:00,ATRO,30.68
9:00:00,ATSG,23.6
9:00:00,ATTU,24.31
9:00:00,ATU,22.44
9:00:00,ATUS,18.62
9:00:00,ATVI,46.1
9:00:00,AU,13.69
9:00:00,AUBN,33.04
9:00:00,AUDC,14.46
9:00:00,AUO,4.0
9:00:00,AUPH,6.34
9:00:00,AUTL,27.82
9:00:00,AUTO,3.1
9:00:00,AUY,2.72
9:00:00,AVA,41.23
9:00:00,AVAL,6.81
9:00:00,AVAV,75.59
9:00:00,AVB,190.0
9:00:00,AVCO,5.76
9:00:00,AVEO,1.74
9:00:00,AVGO,270.68
9:00:00,AVGR,0.32
9:00:00,AVID,4.57
9:00:00,AVLR,38.54
9:00:00,AVNS,44.92
9:00:00,AVP,1.94
9:00:00,AVRO,12.78
9:00:00,AVT,40.3
9:00:00,AVX,17.49
9:00:00,AVY,100.87
9:00:00,AVYA,16.49
9:00:00,AWI,66.46
9:00:00,AWK,93.27
9:00:00,AWP,5.66
9:00:00,AWR,65.33
9:00:00,AWSM,2.82
9:00:00,AX,28.58
9:00:00,AXAS,1.2
9:00:00,AXDX,17.99
9:00:00,AXE,60.78
9:00:00,AXGN,16.42
9:00:00,AXL,14.28
9:00:00,AXNX,14.54
9:00:00,AXON,1.02
9:00:00,AXP,101.15
9:00:00,AXS,54.79
9:00:00,AXSM,8.22
9:00:00,AXTA,26.1
9:00:00,AXTI,3.99
9:00:00,AY,18.31
9:00:00,AYI,119.27
9:00:00,AYR,20.39
9:00:00,AYTU,1.14
9:00:00,AYX,70.39
9:00:00,AZN,36.12
9:00:00,AZO,835.14
9:00:00,AZPN,95.12
9:00:00,AZUL,28.49
9:00:00,B,57.93
9:00:00,BA,384.69
9:00:00,BAB,29.5
9:00:00,BABA,162.54
9:00:00,BABY,33.13
9:00:00,BAC,29.32
9:00:00,BAC-L,1290.27
9:00:00,BAF,13.35
9:00:00,BAH,48.09
9:00:00,BAK,28.2
9:00:00,BAM,42.04
9:00:00,BANC,14.97
9:00:00,BAND,44.37
9:00:00,BANF,53.73
9:00:00,BANR,54.85
9:00:00,BAP,239.81
9:00:00,BAS,4.68
9:00:00,BATRA,26.77
9:00:00,BATRK,26.54
9:00:00,BAX,70.68
9:00:00,BB,7.98
9:00:00,BBBY,14.52
9:00:00,BBCP,8.45
9:00:00,BBD,11.5
9:00:00,BBDC,9.79
9:00:00,BBDO,10.37
9:00:00,BBEU,22.56
9:00:00,BBGI,4.64
9:00:00,BBH,124.6
9:00:00,BBJP,22.3
9:00:00,BBL,43.97
9:00:00,BBN,21.8
9:00:00,BBSI,62.62
9:00:00,BBT,49.2
9:00:00,BBVA,6.02
9:00:00,BBW,4.94
9:00:00,BBX,6.08
9:00:00,BBY,58.92
9:00:00,BC,49.13
9:00:00,BCBP,11.24
9:00:00,BCC,26.25
9:00:00,BCE,42.85
9:00:00,BCEI,23.5
9:00:00,BCML,22.04
9:00:00,BCO,71.56
